Workbook

Sheet GPIO
A1: xczu3eg-sfvc784-1-e
A2: Description | B2: Pin | C2: Pin Name | D2: Bank | E2: PS/PL | F2: EMIO | G2: Offset | H2: Description | K2: J15 (J46)
A3: PS_LED0 | B3: K18 | C3: =_xlfn.IFNA(INDEX(XilinxPins!$B$2:$B$785,MATCH(B3,XilinxPins!$A$2:$A$785,0)), "") -> PS_MIO40 | D3: =_xlfn.IFNA(INDEX(XilinxPins!$D$2:$D$785,MATCH(B3,XilinxPins!$A$2:$A$785,0)), "") -> 501 | E3: =IF(C3="","",IF(ISERROR(FIND("IO_",C3, 1)), "PS", "PL")) -> PS | F3: 0 | G3: =F3 + 78 -> 78 | H3: PL_BTN0 | J3: =INDEX(BoardPins_J45!$C$2:$C$41,MATCH(K3,BoardPins_J45!$A$2:$A$41,0)) -> GND | K3: 1 | L3: 2 | M3: =INDEX(BoardPins_J45!$C$2:$C$41,MATCH(L3,BoardPins_J45!$A$2:$A$41,0)) -> +5V | N3: =_xlfn.IFNA(INDEX($A$3:$A$82,MATCH(L3,$B$3:$B$82,0)), "")
A4: PL_LED0 | B4: AE12 | C4: =_xlfn.IFNA(INDEX(XilinxPins!$B$2:$B$785,MATCH(B4,XilinxPins!$A$2:$A$785,0)), "") -> IO_L5P_HDGC_AD7P_44 | D4: =_xlfn.IFNA(INDEX(XilinxPins!$D$2:$D$785,MATCH(B4,XilinxPins!$A$2:$A$785,0)), "") -> 44 | E4: =IF(C4="","",IF(ISERROR(FIND("IO_",C4, 1)), "PS", "PL")) -> PL | F4: 1 | G4: =F4 + 78 -> 79 | H4: RS485_DE_0 | I4: =_xlfn.IFNA(INDEX($A$2:$A$100,MATCH(J4,$B$2:$B$100,0)), "") | J4: AG11 | K4: 3 | L4: 4 | M4: AF11 | N4: =_xlfn.IFNA(INDEX($A$2:$A$100,MATCH(M4,$B$2:$B$100,0)), "")
A5: PS_BTN0 | B5: L15 | C5: =_xlfn.IFNA(INDEX(XilinxPins!$B$2:$B$785,MATCH(B5,XilinxPins!$A$2:$A$785,0)), "") -> PS_MIO26 | D5: =_xlfn.IFNA(INDEX(XilinxPins!$D$2:$D$785,MATCH(B5,XilinxPins!$A$2:$A$785,0)), "") -> 501 | E5: =IF(C5="","",IF(ISERROR(FIND("IO_",C5, 1)), "PS", "PL")) -> PS | F5: 2 | G5: =F5 + 78 -> 80 | H5: RS485_DE_1 | I5: =_xlfn.IFNA(INDEX($A$2:$A$100,MATCH(J5,$B$2:$B$100,0)), "") | J5: AB14 | K5: 5 | L5: 6 | M5: AB15 | N5: =_xlfn.IFNA(INDEX($A$2:$A$100,MATCH(M5,$B$2:$B$100,0)), "")
A6: PL_BTN0 | B6: AF12 | C6: =_xlfn.IFNA(INDEX(XilinxPins!$B$2:$B$785,MATCH(B6,XilinxPins!$A$2:$A$785,0)), "") -> IO_L5N_HDGC_AD7N_44 | D6: =_xlfn.IFNA(INDEX(XilinxPins!$D$2:$D$785,MATCH(B6,XilinxPins!$A$2:$A$785,0)), "") -> 44 | E6: =IF(C6="","",IF(ISERROR(FIND("IO_",C6, 1)), "PS", "PL")) -> PL | F6: 3 | G6: =F6 + 78 -> 81 | H6: GEM2_PHY_RSTN | I6: =_xlfn.IFNA(INDEX($A$2:$A$100,MATCH(J6,$B$2:$B$100,0)), "") | J6: W13 | K6: 7 | L6: 8 | M6: W14 | N6: =_xlfn.IFNA(INDEX($A$2:$A$100,MATCH(M6,$B$2:$B$100,0)), "")
C7: =_xlfn.IFNA(INDEX(XilinxPins!$B$2:$B$785,MATCH(B7,XilinxPins!$A$2:$A$785,0)), "") | D7: =_xlfn.IFNA(INDEX(XilinxPins!$D$2:$D$785,MATCH(B7,XilinxPins!$A$2:$A$785,0)), "") | E7: =IF(C7="","",IF(ISERROR(FIND("IO_",C7, 1)), "PS", "PL")) | F7: 4 | G7: =F7 + 78 -> 82 | I7: =_xlfn.IFNA(INDEX($A$2:$A$100,MATCH(J7,$B$2:$B$100,0)), "") | J7: W11 | K7: 9 | L7: 10 | M7: W12 | N7: =_xlfn.IFNA(INDEX($A$2:$A$100,MATCH(M7,$B$2:$B$100,0)), "")
C8: =_xlfn.IFNA(INDEX(XilinxPins!$B$2:$B$785,MATCH(B8,XilinxPins!$A$2:$A$785,0)), "") | D8: =_xlfn.IFNA(INDEX(XilinxPins!$D$2:$D$785,MATCH(B8,XilinxPins!$A$2:$A$785,0)), "") | E8: =IF(C8="","",IF(ISERROR(FIND("IO_",C8, 1)), "PS", "PL")) | F8: 5 | G8: =F8 + 78 -> 83 | I8: =_xlfn.IFNA(INDEX($A$2:$A$100,MATCH(J8,$B$2:$B$100,0)), "") | J8: Y10 | K8: 11 | L8: 12 | M8: W10 | N8: =_xlfn.IFNA(INDEX($A$2:$A$100,MATCH(M8,$B$2:$B$100,0)), "")
C9: =_xlfn.IFNA(INDEX(XilinxPins!$B$2:$B$785,MATCH(B9,XilinxPins!$A$2:$A$785,0)), "") | D9: =_xlfn.IFNA(INDEX(XilinxPins!$D$2:$D$785,MATCH(B9,XilinxPins!$A$2:$A$785,0)), "") | E9: =IF(C9="","",IF(ISERROR(FIND("IO_",C9, 1)), "PS", "PL")) | F9: 6 | G9: =F9 + 78 -> 84 | I9: =_xlfn.IFNA(INDEX($A$2:$A$100,MATCH(J9,$B$2:$B$100,0)), "") | J9: AB9 | K9: 13 | L9: 14 | M9: AB10 | N9: =_xlfn.IFNA(INDEX($A$2:$A$100,MATCH(M9,$B$2:$B$100,0)), "")
C10: =_xlfn.IFNA(INDEX(XilinxPins!$B$2:$B$785,MATCH(B10,XilinxPins!$A$2:$A$785,0)), "") | D10: =_xlfn.IFNA(INDEX(XilinxPins!$D$2:$D$785,MATCH(B10,XilinxPins!$A$2:$A$785,0)), "") | E10: =IF(C10="","",IF(ISERROR(FIND("IO_",C10, 1)), "PS", "PL")) | F10: 7 | G10: =F10 + 78 -> 85 | I10: =_xlfn.IFNA(INDEX($A$2:$A$100,MATCH(J10,$B$2:$B$100,0)), "") | J10: AH13 | K10: 15 | L10: 16 | M10: AG13 | N10: =_xlfn.IFNA(INDEX($A$2:$A$100,MATCH(M10,$B$2:$B$100,0)), "")
C11: =_xlfn.IFNA(INDEX(XilinxPins!$B$2:$B$785,MATCH(B11,XilinxPins!$A$2:$A$785,0)), "") | D11: =_xlfn.IFNA(INDEX(XilinxPins!$D$2:$D$785,MATCH(B11,XilinxPins!$A$2:$A$785,0)), "") | E11: =IF(C11="","",IF(ISERROR(FIND("IO_",C11, 1)), "PS", "PL")) | F11: 8 | G11: =F11 + 78 -> 86 | I11: =_xlfn.IFNA(INDEX($A$2:$A$100,MATCH(J11,$B$2:$B$100,0)), "") | J11: AA12 | K11: 17 | L11: 18 | M11: Y12 | N11: =_xlfn.IFNA(INDEX($A$2:$A$100,MATCH(M11,$B$2:$B$100,0)), "")
C12: =_xlfn.IFNA(INDEX(XilinxPins!$B$2:$B$785,MATCH(B12,XilinxPins!$A$2:$A$785,0)), "") | D12: =_xlfn.IFNA(INDEX(XilinxPins!$D$2:$D$785,MATCH(B12,XilinxPins!$A$2:$A$785,0)), "") | E12: =IF(C12="","",IF(ISERROR(FIND("IO_",C12, 1)), "PS", "PL")) | F12: 9 | G12: =F12 + 78 -> 87 | I12: =_xlfn.IFNA(INDEX($A$2:$A$100,MATCH(J12,$B$2:$B$100,0)), "") | J12: AE14 | K12: 19 | L12: 20 | M12: AE15 | N12: =_xlfn.IFNA(INDEX($A$2:$A$100,MATCH(M12,$B$2:$B$100,0)), "")
C13: =_xlfn.IFNA(INDEX(XilinxPins!$B$2:$B$785,MATCH(B13,XilinxPins!$A$2:$A$785,0)), "") | D13: =_xlfn.IFNA(INDEX(XilinxPins!$D$2:$D$785,MATCH(B13,XilinxPins!$A$2:$A$785,0)), "") | E13: =IF(C13="","",IF(ISERROR(FIND("IO_",C13, 1)), "PS", "PL")) | F13: 10 | G13: =F13 + 78 -> 88 | I13: =_xlfn.IFNA(INDEX($A$2:$A$100,MATCH(J13,$B$2:$B$100,0)), "") | J13: AD14 | K13: 21 | L13: 22 | M13: AD15 | N13: =_xlfn.IFNA(INDEX($A$2:$A$100,MATCH(M13,$B$2:$B$100,0)), "")
C14: =_xlfn.IFNA(INDEX(XilinxPins!$B$2:$B$785,MATCH(B14,XilinxPins!$A$2:$A$785,0)), "") | D14: =_xlfn.IFNA(INDEX(XilinxPins!$D$2:$D$785,MATCH(B14,XilinxPins!$A$2:$A$785,0)), "") | E14: =IF(C14="","",IF(ISERROR(FIND("IO_",C14, 1)), "PS", "PL")) | F14: 11 | G14: =F14 + 78 -> 89 | I14: =_xlfn.IFNA(INDEX($A$2:$A$100,MATCH(J14,$B$2:$B$100,0)), "") | J14: AC13 | K14: 23 | L14: 24 | M14: AC14 | N14: =_xlfn.IFNA(INDEX($A$2:$A$100,MATCH(M14,$B$2:$B$100,0)), "")
C15: =_xlfn.IFNA(INDEX(XilinxPins!$B$2:$B$785,MATCH(B15,XilinxPins!$A$2:$A$785,0)), "") | D15: =_xlfn.IFNA(INDEX(XilinxPins!$D$2:$D$785,MATCH(B15,XilinxPins!$A$2:$A$785,0)), "") | E15: =IF(C15="","",IF(ISERROR(FIND("IO_",C15, 1)), "PS", "PL")) | F15: 12 | G15: =F15 + 78 -> 90 | I15: =_xlfn.IFNA(INDEX($A$2:$A$100,MATCH(J15,$B$2:$B$100,0)), "") | J15: Y13 | K15: 25 | L15: 26 | M15: Y14 | N15: =_xlfn.IFNA(INDEX($A$2:$A$100,MATCH(M15,$B$2:$B$100,0)), "")
C16: =_xlfn.IFNA(INDEX(XilinxPins!$B$2:$B$785,MATCH(B16,XilinxPins!$A$2:$A$785,0)), "") | D16: =_xlfn.IFNA(INDEX(XilinxPins!$D$2:$D$785,MATCH(B16,XilinxPins!$A$2:$A$785,0)), "") | E16: =IF(C16="","",IF(ISERROR(FIND("IO_",C16, 1)), "PS", "PL")) | F16: 13 | G16: =F16 + 78 -> 91 | I16: =_xlfn.IFNA(INDEX($A$2:$A$100,MATCH(J16,$B$2:$B$100,0)), "") | J16: AH14 | K16: 27 | L16: 28 | M16: AG14 | N16: =_xlfn.IFNA(INDEX($A$2:$A$100,MATCH(M16,$B$2:$B$100,0)), "")
C17: =_xlfn.IFNA(INDEX(XilinxPins!$B$2:$B$785,MATCH(B17,XilinxPins!$A$2:$A$785,0)), "") | D17: =_xlfn.IFNA(INDEX(XilinxPins!$D$2:$D$785,MATCH(B17,XilinxPins!$A$2:$A$785,0)), "") | E17: =IF(C17="","",IF(ISERROR(FIND("IO_",C17, 1)), "PS", "PL")) | F17: 14 | G17: =F17 + 78 -> 92 | I17: =_xlfn.IFNA(INDEX($A$2:$A$100,MATCH(J17,$B$2:$B$100,0)), "") | J17: AC11 | K17: 29 | L17: 30 | M17: AB11 | N17: =_xlfn.IFNA(INDEX($A$2:$A$100,MATCH(M17,$B$2:$B$100,0)), "")
C18: =_xlfn.IFNA(INDEX(XilinxPins!$B$2:$B$785,MATCH(B18,XilinxPins!$A$2:$A$785,0)), "") | D18: =_xlfn.IFNA(INDEX(XilinxPins!$D$2:$D$785,MATCH(B18,XilinxPins!$A$2:$A$785,0)), "") | E18: =IF(C18="","",IF(ISERROR(FIND("IO_",C18, 1)), "PS", "PL")) | F18: 15 | G18: =F18 + 78 -> 93 | I18: =_xlfn.IFNA(INDEX($A$2:$A$100,MATCH(J18,$B$2:$B$100,0)), "") | J18: AD10 | K18: 31 | L18: 32 | M18: AD11 | N18: =_xlfn.IFNA(INDEX($A$2:$A$100,MATCH(M18,$B$2:$B$100,0)), "")
... C20: =_xlfn.IFNA(INDEX(XilinxPins!$B$2:$B$785,MATCH(B20,XilinxPins!$A$2:$A$785,0)), "") | D20: =_xlfn.IFNA(INDEX(XilinxPins!$D$2:$D$785,MATCH(B20,XilinxPins!$A$2:$A$785,0)), "") | E20: =IF(C20="","",IF(ISERROR(FIND("IO_",C20, 1)), "PS", "PL")) | F20: 17 | G20: =F20 + 78 -> 95 | I20: =_xlfn.IFNA(INDEX($A$2:$A$100,MATCH(J20,$B$2:$B$100,0)), "") | J20: AB13 | K20: 35 | L20: 36 | M20: AA13 | N20: =_xlfn.IFNA(INDEX($A$2:$A$100,MATCH(M20,$B$2:$B$100,0)), "")
C21: =_xlfn.IFNA(INDEX(XilinxPins!$B$2:$B$785,MATCH(B21,XilinxPins!$A$2:$A$785,0)), "") | D21: =_xlfn.IFNA(INDEX(XilinxPins!$D$2:$D$785,MATCH(B21,XilinxPins!$A$2:$A$785,0)), "") | E21: =IF(C21="","",IF(ISERROR(FIND("IO_",C21, 1)), "PS", "PL")) | F21: 18 | G21: =F21 + 78 -> 96 | J21: =INDEX(BoardPins_J45!$C$2:$C$41,MATCH(K21,BoardPins_J45!$A$2:$A$41,0)) -> GND | K21: 37 | L21: 38 | M21: =INDEX(BoardPins_J45!$C$2:$C$41,MATCH(L21,BoardPins_J45!$A$2:$A$41,0)) -> GND | N21: =_xlfn.IFNA(INDEX($A$3:$A$82,MATCH(L21,$B$3:$B$82,0)), "")
C22: =_xlfn.IFNA(INDEX(XilinxPins!$B$2:$B$785,MATCH(B22,XilinxPins!$A$2:$A$785,0)), "") | D22: =_xlfn.IFNA(INDEX(XilinxPins!$D$2:$D$785,MATCH(B22,XilinxPins!$A$2:$A$785,0)), "") | E22: =IF(C22="","",IF(ISERROR(FIND("IO_",C22, 1)), "PS", "PL")) | F22: 19 | G22: =F22 + 78 -> 97 | J22: =INDEX(BoardPins_J45!$C$2:$C$41,MATCH(K22,BoardPins_J45!$A$2:$A$41,0)) -> +3.3V | K22: 39 | L22: 40 | M22: =INDEX(BoardPins_J45!$C$2:$C$41,MATCH(L22,BoardPins_J45!$A$2:$A$41,0)) -> +3.3V | N22: =_xlfn.IFNA(INDEX($A$3:$A$82,MATCH(L22,$B$3:$B$82,0)), "")
C23: =_xlfn.IFNA(INDEX(XilinxPins!$B$2:$B$785,MATCH(B23,XilinxPins!$A$2:$A$785,0)), "") | D23: =_xlfn.IFNA(INDEX(XilinxPins!$D$2:$D$785,MATCH(B23,XilinxPins!$A$2:$A$785,0)), "") | E23: =IF(C23="","",IF(ISERROR(FIND("IO_",C23, 1)), "PS", "PL")) | F23: 20 | G23: =F23 + 78 -> 98
C24: =_xlfn.IFNA(INDEX(XilinxPins!$B$2:$B$785,MATCH(B24,XilinxPins!$A$2:$A$785,0)), "") | D24: =_xlfn.IFNA(INDEX(XilinxPins!$D$2:$D$785,MATCH(B24,XilinxPins!$A$2:$A$785,0)), "") | E24: =IF(C24="","",IF(ISERROR(FIND("IO_",C24, 1)), "PS", "PL")) | F24: 21 | G24: =F24 + 78 -> 99
C25: =_xlfn.IFNA(INDEX(XilinxPins!$B$2:$B$785,MATCH(B25,XilinxPins!$A$2:$A$785,0)), "") | D25: =_xlfn.IFNA(INDEX(XilinxPins!$D$2:$D$785,MATCH(B25,XilinxPins!$A$2:$A$785,0)), "") | E25: =IF(C25="","",IF(ISERROR(FIND("IO_",C25, 1)), "PS", "PL")) | F25: 22 | G25: =F25 + 78 -> 100 | K25: J16 (J45)
C26: =_xlfn.IFNA(INDEX(XilinxPins!$B$2:$B$785,MATCH(B26,XilinxPins!$A$2:$A$785,0)), "") | D26: =_xlfn.IFNA(INDEX(XilinxPins!$D$2:$D$785,MATCH(B26,XilinxPins!$A$2:$A$785,0)), "") | E26: =IF(C26="","",IF(ISERROR(FIND("IO_",C26, 1)), "PS", "PL")) | F26: 23 | G26: =F26 + 78 -> 101 | I26: =_xlfn.IFNA(INDEX($A$3:$A$82,MATCH(J26,$B$3:$B$82,0)), "") | J26: =INDEX(BoardPins_J46!$C$2:$C$41,MATCH(K26,BoardPins_J46!$A$2:$A$41,0)) -> GND | K26: 1 | L26: 2 | M26: =INDEX(BoardPins_J46!$C$2:$C$41,MATCH(L26,BoardPins_J46!$A$2:$A$41,0)) -> +5V | N26: =_xlfn.IFNA(INDEX($A$3:$A$82,MATCH(L26,$B$3:$B$82,0)), "")
C27: =_xlfn.IFNA(INDEX(XilinxPins!$B$2:$B$785,MATCH(B27,XilinxPins!$A$2:$A$785,0)), "") | D27: =_xlfn.IFNA(INDEX(XilinxPins!$D$2:$D$785,MATCH(B27,XilinxPins!$A$2:$A$785,0)), "") | E27: =IF(C27="","",IF(ISERROR(FIND("IO_",C27, 1)), "PS", "PL")) | F27: 24 | G27: =F27 + 78 -> 102 | I27: =_xlfn.IFNA(INDEX($A$2:$A$100,MATCH(J27,$B$2:$B$100,0)), "") | J27: B10 | K27: 3 | L27: 4 | M27: C11 | N27: =_xlfn.IFNA(INDEX($A$2:$A$100,MATCH(M27,$B$2:$B$100,0)), "")
C28: =_xlfn.IFNA(INDEX(XilinxPins!$B$2:$B$785,MATCH(B28,XilinxPins!$A$2:$A$785,0)), "") | D28: =_xlfn.IFNA(INDEX(XilinxPins!$D$2:$D$785,MATCH(B28,XilinxPins!$A$2:$A$785,0)), "") | E28: =IF(C28="","",IF(ISERROR(FIND("IO_",C28, 1)), "PS", "PL")) | F28: 25 | G28: =F28 + 78 -> 103 | I28: =_xlfn.IFNA(INDEX($A$2:$A$100,MATCH(J28,$B$2:$B$100,0)), "") | J28: F10 | K28: 5 | L28: 6 | M28: G11 | N28: =_xlfn.IFNA(INDEX($A$2:$A$100,MATCH(M28,$B$2:$B$100,0)), "")
C29: =_xlfn.IFNA(INDEX(XilinxPins!$B$2:$B$785,MATCH(B29,XilinxPins!$A$2:$A$785,0)), "") | D29: =_xlfn.IFNA(INDEX(XilinxPins!$D$2:$D$785,MATCH(B29,XilinxPins!$A$2:$A$785,0)), "") | E29: =IF(C29="","",IF(ISERROR(FIND("IO_",C29, 1)), "PS", "PL")) | F29: 26 | G29: =F29 + 78 -> 104 | I29: =_xlfn.IFNA(INDEX($A$2:$A$100,MATCH(J29,$B$2:$B$100,0)), "") | J29: C12 | K29: 7 | L29: 8 | M29: D12 | N29: =_xlfn.IFNA(INDEX($A$2:$A$100,MATCH(M29,$B$2:$B$100,0)), "")
C30: =_xlfn.IFNA(INDEX(XilinxPins!$B$2:$B$785,MATCH(B30,XilinxPins!$A$2:$A$785,0)), "") | D30: =_xlfn.IFNA(INDEX(XilinxPins!$D$2:$D$785,MATCH(B30,XilinxPins!$A$2:$A$785,0)), "") | E30: =IF(C30="","",IF(ISERROR(FIND("IO_",C30, 1)), "PS", "PL")) | F30: 27 | G30: =F30 + 78 -> 105 | I30: =_xlfn.IFNA(INDEX($A$2:$A$100,MATCH(J30,$B$2:$B$100,0)), "") | J30: A11 | K30: 9 | L30: 10 | M30: A12 | N30: =_xlfn.IFNA(INDEX($A$2:$A$100,MATCH(M30,$B$2:$B$100,0)), "")
C31: =_xlfn.IFNA(INDEX(XilinxPins!$B$2:$B$785,MATCH(B31,XilinxPins!$A$2:$A$785,0)), "") | D31: =_xlfn.IFNA(INDEX(XilinxPins!$D$2:$D$785,MATCH(B31,XilinxPins!$A$2:$A$785,0)), "") | E31: =IF(C31="","",IF(ISERROR(FIND("IO_",C31, 1)), "PS", "PL")) | F31: 28 | G31: =F31 + 78 -> 106 | I31: =_xlfn.IFNA(INDEX($A$2:$A$100,MATCH(J31,$B$2:$B$100,0)), "") | J31: F11 | K31: 11 | L31: 12 | M31: F12 | N31: =_xlfn.IFNA(INDEX($A$2:$A$100,MATCH(M31,$B$2:$B$100,0)), "")
C32: =_xlfn.IFNA(INDEX(XilinxPins!$B$2:$B$785,MATCH(B32,XilinxPins!$A$2:$A$785,0)), "") | D32: =_xlfn.IFNA(INDEX(XilinxPins!$D$2:$D$785,MATCH(B32,XilinxPins!$A$2:$A$785,0)), "") | E32: =IF(C32="","",IF(ISERROR(FIND("IO_",C32, 1)), "PS", "PL")) | F32: 29 | G32: =F32 + 78 -> 107 | I32: =_xlfn.IFNA(INDEX($A$2:$A$100,MATCH(J32,$B$2:$B$100,0)), "") | J32: E13 | K32: 13 | L32: 14 | M32: E14 | N32: =_xlfn.IFNA(INDEX($A$2:$A$100,MATCH(M32,$B$2:$B$100,0)), "")
C33: =_xlfn.IFNA(INDEX(XilinxPins!$B$2:$B$785,MATCH(B33,XilinxPins!$A$2:$A$785,0)), "") | D33: =_xlfn.IFNA(INDEX(XilinxPins!$D$2:$D$785,MATCH(B33,XilinxPins!$A$2:$A$785,0)), "") | E33: =IF(C33="","",IF(ISERROR(FIND("IO_",C33, 1)), "PS", "PL")) | F33: 30 | G33: =F33 + 78 -> 108 | I33: =_xlfn.IFNA(INDEX($A$2:$A$100,MATCH(J33,$B$2:$B$100,0)), "") | J33: A13 | K33: 15 | L33: 16 | M33: B13 | N33: =_xlfn.IFNA(INDEX($A$2:$A$100,MATCH(M33,$B$2:$B$100,0)), "")
C34: =_xlfn.IFNA(INDEX(XilinxPins!$B$2:$B$785,MATCH(B34,XilinxPins!$A$2:$A$785,0)), "") | D34: =_xlfn.IFNA(INDEX(XilinxPins!$D$2:$D$785,MATCH(B34,XilinxPins!$A$2:$A$785,0)), "") | E34: =IF(C34="","",IF(ISERROR(FIND("IO_",C34, 1)), "PS", "PL")) | F34: 31 | G34: =F34 + 78 -> 109 | I34: =_xlfn.IFNA(INDEX($A$2:$A$100,MATCH(J34,$B$2:$B$100,0)), "") | J34: A14 | K34: 17 | L34: 18 | M34: B14 | N34: =_xlfn.IFNA(INDEX($A$2:$A$100,MATCH(M34,$B$2:$B$100,0)), "")
C35: =_xlfn.IFNA(INDEX(XilinxPins!$B$2:$B$785,MATCH(B35,XilinxPins!$A$2:$A$785,0)), "") | D35: =_xlfn.IFNA(INDEX(XilinxPins!$D$2:$D$785,MATCH(B35,XilinxPins!$A$2:$A$785,0)), "") | E35: =IF(C35="","",IF(ISERROR(FIND("IO_",C35, 1)), "PS", "PL")) | F35: 32 | G35: =F35 + 78 -> 110 | I35: =_xlfn.IFNA(INDEX($A$2:$A$100,MATCH(J35,$B$2:$B$100,0)), "") | J35: C13 | K35: 19 | L35: 20 | M35: C14 | N35: =_xlfn.IFNA(INDEX($A$2:$A$100,MATCH(M35,$B$2:$B$100,0)), "")
C36: =_xlfn.IFNA(INDEX(XilinxPins!$B$2:$B$785,MATCH(B36,XilinxPins!$A$2:$A$785,0)), "") | D36: =_xlfn.IFNA(INDEX(XilinxPins!$D$2:$D$785,MATCH(B36,XilinxPins!$A$2:$A$785,0)), "") | E36: =IF(C36="","",IF(ISERROR(FIND("IO_",C36, 1)), "PS", "PL")) | F36: 33 | G36: =F36 + 78 -> 111 | I36: =_xlfn.IFNA(INDEX($A$2:$A$100,MATCH(J36,$B$2:$B$100,0)), "") | J36: L13 | K36: 21 | L36: 22 | M36: L14 | N36: =_xlfn.IFNA(INDEX($A$2:$A$100,MATCH(M36,$B$2:$B$100,0)), "")
C37: =_xlfn.IFNA(INDEX(XilinxPins!$B$2:$B$785,MATCH(B37,XilinxPins!$A$2:$A$785,0)), "") | D37: =_xlfn.IFNA(INDEX(XilinxPins!$D$2:$D$785,MATCH(B37,XilinxPins!$A$2:$A$785,0)), "") | E37: =IF(C37="","",IF(ISERROR(FIND("IO_",C37, 1)), "PS", "PL")) | F37: 34 | G37: =F37 + 78 -> 112 | I37: =_xlfn.IFNA(INDEX($A$2:$A$100,MATCH(J37,$B$2:$B$100,0)), "") | J37: H12 | K37: 23 | L37: 24 | M37: J12 | N37: =_xlfn.IFNA(INDEX($A$2:$A$100,MATCH(M37,$B$2:$B$100,0)), "")
C38: =_xlfn.IFNA(INDEX(XilinxPins!$B$2:$B$785,MATCH(B38,XilinxPins!$A$2:$A$785,0)), "") | D38: =_xlfn.IFNA(INDEX(XilinxPins!$D$2:$D$785,MATCH(B38,XilinxPins!$A$2:$A$785,0)), "") | E38: =IF(C38="","",IF(ISERROR(FIND("IO_",C38, 1)), "PS", "PL")) | F38: 35 | G38: =F38 + 78 -> 113 | I38: =_xlfn.IFNA(INDEX($A$2:$A$100,MATCH(J38,$B$2:$B$100,0)), "") | J38: J14 | K38: 25 | L38: 26 | M38: K14 | N38: =_xlfn.IFNA(INDEX($A$2:$A$100,MATCH(M38,$B$2:$B$100,0)), "")
... C43: =_xlfn.IFNA(INDEX(XilinxPins!$B$2:$B$785,MATCH(B43,XilinxPins!$A$2:$A$785,0)), "") | D43: =_xlfn.IFNA(INDEX(XilinxPins!$D$2:$D$785,MATCH(B43,XilinxPins!$A$2:$A$785,0)), "") | E43: =IF(C43="","",IF(ISERROR(FIND("IO_",C43, 1)), "PS", "PL")) | F43: 40 | G43: =F43 + 78 -> 118 | I43: =_xlfn.IFNA(INDEX($A$2:$A$100,MATCH(J43,$B$2:$B$100,0)), "") | J43: A15 | K43: 35 | L43: 36 | M43: B15 | N43: =_xlfn.IFNA(INDEX($A$2:$A$100,MATCH(M43,$B$2:$B$100,0)), "")
C44: =_xlfn.IFNA(INDEX(XilinxPins!$B$2:$B$785,MATCH(B44,XilinxPins!$A$2:$A$785,0)), "") | D44: =_xlfn.IFNA(INDEX(XilinxPins!$D$2:$D$785,MATCH(B44,XilinxPins!$A$2:$A$785,0)), "") | E44: =IF(C44="","",IF(ISERROR(FIND("IO_",C44, 1)), "PS", "PL")) | F44: 41 | G44: =F44 + 78 -> 119 | I44: =_xlfn.IFNA(INDEX($A$3:$A$82,MATCH(J44,$B$3:$B$82,0)), "") | J44: =INDEX(BoardPins_J46!$C$2:$C$41,MATCH(K44,BoardPins_J46!$A$2:$A$41,0)) -> GND | K44: 37 | L44: 38 | M44: =INDEX(BoardPins_J46!$C$2:$C$41,MATCH(L44,BoardPins_J46!$A$2:$A$41,0)) -> GND | N44: =_xlfn.IFNA(INDEX($A$3:$A$82,MATCH(L44,$B$3:$B$82,0)), "")
C45: =_xlfn.IFNA(INDEX(XilinxPins!$B$2:$B$785,MATCH(B45,XilinxPins!$A$2:$A$785,0)), "") | D45: =_xlfn.IFNA(INDEX(XilinxPins!$D$2:$D$785,MATCH(B45,XilinxPins!$A$2:$A$785,0)), "") | E45: =IF(C45="","",IF(ISERROR(FIND("IO_",C45, 1)), "PS", "PL")) | F45: 42 | G45: =F45 + 78 -> 120 | I45: =_xlfn.IFNA(INDEX($A$3:$A$82,MATCH(J45,$B$3:$B$82,0)), "") | J45: =INDEX(BoardPins_J46!$C$2:$C$41,MATCH(K45,BoardPins_J46!$A$2:$A$41,0)) -> +3.3V | K45: 39 | L45: 40 | M45: =INDEX(BoardPins_J46!$C$2:$C$41,MATCH(L45,BoardPins_J46!$A$2:$A$41,0)) -> +3.3V | N45: =_xlfn.IFNA(INDEX($A$3:$A$82,MATCH(L45,$B$3:$B$82,0)), "")
...

Sheet MEMORY
B2: Size | C2: Begin Address | D2: End Address
A3: PS DDR 0 | B3: 7FF00000 | C3: 0 | D3: =DEC2HEX(HEX2DEC(C3) + HEX2DEC(B3) - 1) -> 7FEFFFFF
A4: PS DDR 1 | B4: 80000000 | C4: 800000000 | D4: =DEC2HEX(HEX2DEC(C4) + HEX2DEC(B4) - 1) -> 87FFFFFFF
A5: PL DDR | B5: 40000000 | C5: 400000000 | D5: =DEC2HEX(HEX2DEC(C5) + HEX2DEC(B5) - 1) -> 43FFFFFFF
A9: Total DDR | B9: =DEC2HEX(HEX2DEC(B3) + HEX2DEC(B4) + HEX2DEC(B5) ) -> 13FF00000
B12: Size | C12: Begin Address | D12: End Address
A13: RPU0 | B13: 4000000 | C13: 100000 | D13: =DEC2HEX(HEX2DEC(C13) + HEX2DEC(B13) - 1) -> 40FFFFF
A14: RPU1 | B14: 4000000 | C14: =DEC2HEX(HEX2DEC(C13) + HEX2DEC(B13)) -> 4100000 | D14: =DEC2HEX(HEX2DEC(C14) + HEX2DEC(B14) - 1) -> 80FFFFF
A15: APU0 | B15: 20000000 | C15: =DEC2HEX(HEX2DEC(C14) + HEX2DEC(B14)) -> 8100000 | D15: =DEC2HEX(HEX2DEC(C15) + HEX2DEC(B15) - 1) -> 280FFFFF
A16: APU1 | B16: 20000000 | C16: =DEC2HEX(HEX2DEC(C15) + HEX2DEC(B15)) -> 28100000 | D16: =DEC2HEX(HEX2DEC(C16) + HEX2DEC(B16) - 1) -> 480FFFFF
A17: APU2 | B17: 20000000 | C17: =DEC2HEX(HEX2DEC(C16) + HEX2DEC(B16)) -> 48100000 | D17: =DEC2HEX(HEX2DEC(C17) + HEX2DEC(B17) - 1) -> 680FFFFF
A18: APU3 | B18: 20000000 | C18: =DEC2HEX(HEX2DEC(C17) + HEX2DEC(B17)) -> 68100000 | D18: =DEC2HEX(HEX2DEC(C18) + HEX2DEC(B18) - 1) -> 880FFFFF

Sheet XilinxPins
A1: Pin | B1: Pin Name | C1: Memory Byte Group | D1: Bank | E1: I/O Type | F1: Super Logic Region
A2: U12 | B2: DXN
A3: P12 | B3: VCCADC
A4: P13 | B4: GNDADC
A5: U13 | B5: DXP
A6: T13 | B6: VREFP
A7: R12 | B7: VREFN
A8: R13 | B8: VP
A9: T12 | B9: VN
A10: U7 | B10: PUDC_B | D10: 0 | E10: CONFIG
A11: W7 | B11: POR_OVERRIDE
A12: L13 | B12: IO_L12N_AD0N_26 | D12: 26 | E12: HD
A13: L14 | B13: IO_L12P_AD0P_26 | D13: 26 | E13: HD
A14: J14 | B14: IO_L11N_AD1N_26 | D14: 26 | E14: HD
A15: K14 | B15: IO_L11P_AD1P_26 | D15: 26 | E15: HD
A16: H13 | B16: IO_L10N_AD2N_26 | D16: 26 | E16: HD
A17: H14 | B17: IO_L10P_AD2P_26 | D17: 26 | E17: HD
A18: G14 | B18: IO_L9N_AD3N_26 | D18: 26 | E18: HD
A19: G15 | B19: IO_L9P_AD3P_26 | D19: 26 | E19: HD
A20: E15 | B20: IO_L8N_HDGC_AD4N_26 | D20: 26 | E20: HD
A21: F15 | B21: IO_L8P_HDGC_AD4P_26 | D21: 26 | E21: HD
A22: F13 | B22: IO_L7N_HDGC_AD5N_26 | D22: 26 | E22: HD
A23: G13 | B23: IO_L7P_HDGC_AD5P_26 | D23: 26 | E23: HD
... A107: AG10 | B107: IO_L1P_AD11P_44 | D107: 44 | E107: HD
A108: B9 | B108: IO_L24N_T3U_N11_66 | C108: 3U | D108: 66 | E108: HP
A109: C9 | B109: IO_L24P_T3U_N10_66 | C109: 3U | D109: 66 | E109: HP
A110: A8 | B110: IO_L23N_T3U_N9_66 | C110: 3U | D110: 66 | E110: HP
A111: A9 | B111: IO_L23P_T3U_N8_66 | C111: 3U | D111: 66 | E111: HP
A112: B8 | B112: IO_L22N_T3U_N7_DBC_AD0N_66 | C112: 3U | D112: 66 | E112: HP
A113: C8 | B113: IO_L22P_T3U_N6_DBC_AD0P_66 | C113: 3U | D113: 66 | E113: HP
A114: A6 | B114: IO_L21N_T3L_N5_AD8N_66 | C114: 3L | D114: 66 | E114: HP
A115: A7 | B115: IO_L21P_T3L_N4_AD8P_66 | C115: 3L | D115: 66 | E115: HP
A116: B6 | B116: IO_L20N_T3L_N3_AD1N_66 | C116: 3L | D116: 66 | E116: HP
A117: C6 | B117: IO_L20P_T3L_N2_AD1P_66 | C117: 3L | D117: 66 | E117: HP
A118: A5 | B118: IO_L19N_T3L_N1_DBC_AD9N_66 | C118: 3L | D118: 66 | E118: HP
A119: B5 | B119: IO_L19P_T3L_N0_DBC_AD9P_66 | C119: 3L | D119: 66 | E119: HP
... A159: G1 | B159: IO_L1P_T0L_N0_DBC_66 | C159: 0L | D159: 66 | E159: HP
A160: G9 | B160: VREF_66 | D160: 66 | E160: HP
A161: H8 | B161: IO_L24N_T3U_N11_PERSTN0_65 | C161: 3U | D161: 65 | E161: HP
A162: H9 | B162: IO_L24P_T3U_N10_PERSTN1_I2C_SDA_65 | C162: 3U | D162: 65 | E162: HP
...

Sheet BoardPins_J46
A1: J46 Pin | B1: Signal name | C1: Pin Number
A2: 1 | B2: GND | C2: GND
A3: 2 | B3: +5V | C3: +5V
A4: 3 | B4: B43_L2_N | C4: AG11
A5: 4 | B5: IO2_1P | C5: Y14
A6: 5 | B6: B44_L8_N | C6: AB14
A7: 6 | B7: IO2_2P | C7: AA13
A8: 7 | B8: B44_L9_N | C8: W13
A9: 8 | B9: IO2_3P | C9: AC12
A10: 9 | B10: B44_L11_N | C10: W11
A11: 10 | B11: IO2_4P | C11: AD11
A12: 11 | B12: B43_L10_N | C12: Y10
A13: 12 | B13: IO2_5P | C13: AB11
... A41: 40 | B41: +3.3V | C41: +3.3V

Sheet BoardPins_J45
A1: J45 Pin | B1: Signal name | C1: Pin Number
A2: 1 | B2: GND | C2: GND
A3: 2 | B3: +5V | C3: +5V
A4: 3 | B4: B45_L9_N | C4: B10
A5: 4 | B5: B45_L9_P | C5: C11
A6: 5 | B6: B45_L5_N | C6: F10
A7: 6 | B7: B45_L5_P | C7: G11
A8: 7 | B8: B45_L12_N | C8: C12
A9: 8 | B9: B45_L12_P | C9: D12
A10: 9 | B10: B45_L11_N | C10: A11
A11: 10 | B11: B45_L11_P | C11: A12
A12: 11 | B12: B45_L6_N | C12: F11
A13: 12 | B13: B45_L6_P | C13: F12
... A41: 40 | B41: +3.3V | C41: +3.3V
